2021-09-30 20:43:47,769 ERROR: Exception on /download [GET] [in c:\users\penie\brain_test\venv\lib\site-packages\flask\app.py:1454
Traceback (most recent call last):
  File "c:\users\penie\brain_test\venv\lib\site-packages\flask\app.py", line 2070, in wsgi_app
    response = self.full_dispatch_request()
  File "c:\users\penie\brain_test\venv\lib\site-packages\flask\app.py", line 1515, in full_dispatch_request
    rv = self.handle_user_exception(e)
  File "c:\users\penie\brain_test\venv\lib\site-packages\flask\app.py", line 1513, in full_dispatch_request
    rv = self.dispatch_request()
  File "c:\users\penie\brain_test\venv\lib\site-packages\flask\app.py", line 1499, in dispatch_request
    return self.ensure_sync(self.view_functions[rule.endpoint])(**req.view_args)
  File "c:\users\penie\brain_test\venv\lib\site-packages\flask_login\utils.py", line 272, in decorated_view
    return func(*args, **kwargs)
  File "C:\Users\penie\brain_test\app\routes.py", line 197, in download
    throw_error = testme
NameError: name 'testme' is not defined
2021-09-30 20:47:44,924 ERROR: Exception on /download [GET] [in c:\users\penie\brain_test\venv\lib\site-packages\flask\app.py:1454
Traceback (most recent call last):
  File "c:\users\penie\brain_test\venv\lib\site-packages\flask\app.py", line 2070, in wsgi_app
    response = self.full_dispatch_request()
  File "c:\users\penie\brain_test\venv\lib\site-packages\flask\app.py", line 1515, in full_dispatch_request
    rv = self.handle_user_exception(e)
  File "c:\users\penie\brain_test\venv\lib\site-packages\flask\app.py", line 1513, in full_dispatch_request
    rv = self.dispatch_request()
  File "c:\users\penie\brain_test\venv\lib\site-packages\flask\app.py", line 1499, in dispatch_request
    return self.ensure_sync(self.view_functions[rule.endpoint])(**req.view_args)
  File "c:\users\penie\brain_test\venv\lib\site-packages\flask_login\utils.py", line 272, in decorated_view
    return func(*args, **kwargs)
  File "C:\Users\penie\brain_test\app\routes.py", line 197, in download
    throw_error = testme
NameError: name 'testme' is not defined
2021-09-30 21:32:47,161 ERROR: Exception on /download [GET] [in c:\users\penie\brain_test\venv\lib\site-packages\flask\app.py:1454
Traceback (most recent call last):
  File "c:\users\penie\brain_test\venv\lib\site-packages\flask\app.py", line 2070, in wsgi_app
    response = self.full_dispatch_request()
  File "c:\users\penie\brain_test\venv\lib\site-packages\flask\app.py", line 1515, in full_dispatch_request
    rv = self.handle_user_exception(e)
  File "c:\users\penie\brain_test\venv\lib\site-packages\flask\app.py", line 1513, in full_dispatch_request
    rv = self.dispatch_request()
  File "c:\users\penie\brain_test\venv\lib\site-packages\flask\app.py", line 1499, in dispatch_request
    return self.ensure_sync(self.view_functions[rule.endpoint])(**req.view_args)
  File "c:\users\penie\brain_test\venv\lib\site-packages\flask_login\utils.py", line 272, in decorated_view
    return func(*args, **kwargs)
  File "C:\Users\penie\brain_test\app\routes.py", line 197, in download
    throw_error = testme
NameError: name 'testme' is not defined
2021-09-30 21:33:47,710 ERROR: Exception on /download [GET] [in c:\users\penie\brain_test\venv\lib\site-packages\flask\app.py:1454
Traceback (most recent call last):
  File "c:\users\penie\brain_test\venv\lib\site-packages\flask\app.py", line 2070, in wsgi_app
    response = self.full_dispatch_request()
  File "c:\users\penie\brain_test\venv\lib\site-packages\flask\app.py", line 1515, in full_dispatch_request
    rv = self.handle_user_exception(e)
  File "c:\users\penie\brain_test\venv\lib\site-packages\flask\app.py", line 1513, in full_dispatch_request
    rv = self.dispatch_request()
  File "c:\users\penie\brain_test\venv\lib\site-packages\flask\app.py", line 1499, in dispatch_request
    return self.ensure_sync(self.view_functions[rule.endpoint])(**req.view_args)
  File "c:\users\penie\brain_test\venv\lib\site-packages\flask_login\utils.py", line 272, in decorated_view
    return func(*args, **kwargs)
  File "C:\Users\penie\brain_test\app\routes.py", line 197, in download
    throw_error = testme
NameError: name 'testme' is not defined
2021-09-30 21:39:36,500 ERROR: Exception on /download [GET] [in c:\users\penie\brain_test\venv\lib\site-packages\flask\app.py:1454
Traceback (most recent call last):
  File "c:\users\penie\brain_test\venv\lib\site-packages\flask\app.py", line 2070, in wsgi_app
    response = self.full_dispatch_request()
  File "c:\users\penie\brain_test\venv\lib\site-packages\flask\app.py", line 1515, in full_dispatch_request
    rv = self.handle_user_exception(e)
  File "c:\users\penie\brain_test\venv\lib\site-packages\flask\app.py", line 1513, in full_dispatch_request
    rv = self.dispatch_request()
  File "c:\users\penie\brain_test\venv\lib\site-packages\flask\app.py", line 1499, in dispatch_request
    return self.ensure_sync(self.view_functions[rule.endpoint])(**req.view_args)
  File "c:\users\penie\brain_test\venv\lib\site-packages\flask_login\utils.py", line 272, in decorated_view
    return func(*args, **kwargs)
  File "C:\Users\penie\brain_test\app\routes.py", line 197, in download
    throw_error = testme
NameError: name 'testme' is not defined
2021-09-30 21:41:24,812 ERROR: Exception on /download [GET] [in c:\users\penie\brain_test\venv\lib\site-packages\flask\app.py:1454
Traceback (most recent call last):
  File "c:\users\penie\brain_test\venv\lib\site-packages\flask\app.py", line 2070, in wsgi_app
    response = self.full_dispatch_request()
  File "c:\users\penie\brain_test\venv\lib\site-packages\flask\app.py", line 1515, in full_dispatch_request
    rv = self.handle_user_exception(e)
  File "c:\users\penie\brain_test\venv\lib\site-packages\flask\app.py", line 1513, in full_dispatch_request
    rv = self.dispatch_request()
  File "c:\users\penie\brain_test\venv\lib\site-packages\flask\app.py", line 1499, in dispatch_request
    return self.ensure_sync(self.view_functions[rule.endpoint])(**req.view_args)
  File "c:\users\penie\brain_test\venv\lib\site-packages\flask_login\utils.py", line 272, in decorated_view
    return func(*args, **kwargs)
  File "C:\Users\penie\brain_test\app\routes.py", line 197, in download
    throw_error = testme
NameError: name 'testme' is not defined
2021-09-30 21:50:45,220 ERROR: Exception on /download [GET] [in c:\users\penie\brain_test\venv\lib\site-packages\flask\app.py:1454
Traceback (most recent call last):
  File "c:\users\penie\brain_test\venv\lib\site-packages\flask\app.py", line 2070, in wsgi_app
    response = self.full_dispatch_request()
  File "c:\users\penie\brain_test\venv\lib\site-packages\flask\app.py", line 1515, in full_dispatch_request
    rv = self.handle_user_exception(e)
  File "c:\users\penie\brain_test\venv\lib\site-packages\flask\app.py", line 1513, in full_dispatch_request
    rv = self.dispatch_request()
  File "c:\users\penie\brain_test\venv\lib\site-packages\flask\app.py", line 1499, in dispatch_request
    return self.ensure_sync(self.view_functions[rule.endpoint])(**req.view_args)
  File "c:\users\penie\brain_test\venv\lib\site-packages\flask_login\utils.py", line 272, in decorated_view
    return func(*args, **kwargs)
  File "C:\Users\penie\brain_test\app\routes.py", line 197, in download
    throw_error = testme
NameError: name 'testme' is not defined
2021-09-30 22:17:57,496 ERROR: Exception on /download [GET] [in c:\users\penie\brain_test\venv\lib\site-packages\flask\app.py:1454
Traceback (most recent call last):
  File "c:\users\penie\brain_test\venv\lib\site-packages\flask\app.py", line 2070, in wsgi_app
    response = self.full_dispatch_request()
  File "c:\users\penie\brain_test\venv\lib\site-packages\flask\app.py", line 1515, in full_dispatch_request
    rv = self.handle_user_exception(e)
  File "c:\users\penie\brain_test\venv\lib\site-packages\flask\app.py", line 1513, in full_dispatch_request
    rv = self.dispatch_request()
  File "c:\users\penie\brain_test\venv\lib\site-packages\flask\app.py", line 1499, in dispatch_request
    return self.ensure_sync(self.view_functions[rule.endpoint])(**req.view_args)
  File "c:\users\penie\brain_test\venv\lib\site-packages\flask_login\utils.py", line 272, in decorated_view
    return func(*args, **kwargs)
  File "C:\Users\penie\brain_test\app\routes.py", line 197, in download
    throw_error = testme
NameError: name 'testme' is not defined
