2021-08-17 06:51:23,551 ERROR: Exception on /uploader [GET] [in c:\users\penie\brain_test\venv\lib\site-packages\flask\app.py:1454
Traceback (most recent call last):
  File "c:\users\penie\brain_test\venv\lib\site-packages\flask\app.py", line 2070, in wsgi_app
    response = self.full_dispatch_request()
  File "c:\users\penie\brain_test\venv\lib\site-packages\flask\app.py", line 1515, in full_dispatch_request
    rv = self.handle_user_exception(e)
  File "c:\users\penie\brain_test\venv\lib\site-packages\flask\app.py", line 1513, in full_dispatch_request
    rv = self.dispatch_request()
  File "c:\users\penie\brain_test\venv\lib\site-packages\flask\app.py", line 1499, in dispatch_request
    return self.ensure_sync(self.view_functions[rule.endpoint])(**req.view_args)
  File "c:\users\penie\brain_test\venv\lib\site-packages\flask_login\utils.py", line 272, in decorated_view
    return func(*args, **kwargs)
  File "C:\Users\penie\brain_test\app\routes.py", line 100, in uploader
    files = os.listdir('app/static/uploads')
FileNotFoundError: [WinError 3] The system cannot find the path specified: 'static/uploads'
2021-08-17 06:51:41,801 ERROR: Exception on /uploader [GET] [in c:\users\penie\brain_test\venv\lib\site-packages\flask\app.py:1454
Traceback (most recent call last):
  File "c:\users\penie\brain_test\venv\lib\site-packages\flask\app.py", line 2070, in wsgi_app
    response = self.full_dispatch_request()
  File "c:\users\penie\brain_test\venv\lib\site-packages\flask\app.py", line 1515, in full_dispatch_request
    rv = self.handle_user_exception(e)
  File "c:\users\penie\brain_test\venv\lib\site-packages\flask\app.py", line 1513, in full_dispatch_request
    rv = self.dispatch_request()
  File "c:\users\penie\brain_test\venv\lib\site-packages\flask\app.py", line 1499, in dispatch_request
    return self.ensure_sync(self.view_functions[rule.endpoint])(**req.view_args)
  File "c:\users\penie\brain_test\venv\lib\site-packages\flask_login\utils.py", line 272, in decorated_view
    return func(*args, **kwargs)
  File "C:\Users\penie\brain_test\app\routes.py", line 100, in uploader
    files = os.listdir('app/static/uploads')
FileNotFoundError: [WinError 3] The system cannot find the path specified: 'static/uploads'
2021-08-17 06:53:41,279 ERROR: Exception on /uploader [GET] [in c:\users\penie\brain_test\venv\lib\site-packages\flask\app.py:1454
Traceback (most recent call last):
  File "c:\users\penie\brain_test\venv\lib\site-packages\flask\app.py", line 2070, in wsgi_app
    response = self.full_dispatch_request()
  File "c:\users\penie\brain_test\venv\lib\site-packages\flask\app.py", line 1515, in full_dispatch_request
    rv = self.handle_user_exception(e)
  File "c:\users\penie\brain_test\venv\lib\site-packages\flask\app.py", line 1513, in full_dispatch_request
    rv = self.dispatch_request()
  File "c:\users\penie\brain_test\venv\lib\site-packages\flask\app.py", line 1499, in dispatch_request
    return self.ensure_sync(self.view_functions[rule.endpoint])(**req.view_args)
  File "c:\users\penie\brain_test\venv\lib\site-packages\flask_login\utils.py", line 272, in decorated_view
    return func(*args, **kwargs)
  File "C:\Users\penie\brain_test\app\routes.py", line 106, in uploader
    return render_template('uploader.html', form=form, files=files)
  File "c:\users\penie\brain_test\venv\lib\site-packages\flask\templating.py", line 148, in render_template
    ctx.app.jinja_env.get_or_select_template(template_name_or_list),
  File "c:\users\penie\brain_test\venv\lib\site-packages\jinja2\environment.py", line 1068, in get_or_select_template
    return self.get_template(template_name_or_list, parent, globals)
  File "c:\users\penie\brain_test\venv\lib\site-packages\jinja2\environment.py", line 997, in get_template
    return self._load_template(name, globals)
  File "c:\users\penie\brain_test\venv\lib\site-packages\jinja2\environment.py", line 958, in _load_template
    template = self.loader.load(self, name, self.make_globals(globals))
  File "c:\users\penie\brain_test\venv\lib\site-packages\jinja2\loaders.py", line 137, in load
    code = environment.compile(source, name, filename)
  File "c:\users\penie\brain_test\venv\lib\site-packages\jinja2\environment.py", line 757, in compile
    self.handle_exception(source=source_hint)
  File "c:\users\penie\brain_test\venv\lib\site-packages\jinja2\environment.py", line 925, in handle_exception
    raise rewrite_traceback_stack(source=source)
  File "C:\Users\penie\brain_test\app\templates\uploader.html", line 14, in template
    <img src="{{ url_for('static', filename=uploads/{{file}}) }}" width="200" height="200">
jinja2.exceptions.TemplateSyntaxError: expected token ':', got '}'
2021-08-17 06:57:12,629 ERROR: Exception on /uploader [GET] [in c:\users\penie\brain_test\venv\lib\site-packages\flask\app.py:1454
Traceback (most recent call last):
  File "c:\users\penie\brain_test\venv\lib\site-packages\flask\app.py", line 2070, in wsgi_app
    response = self.full_dispatch_request()
  File "c:\users\penie\brain_test\venv\lib\site-packages\flask\app.py", line 1515, in full_dispatch_request
    rv = self.handle_user_exception(e)
  File "c:\users\penie\brain_test\venv\lib\site-packages\flask\app.py", line 1513, in full_dispatch_request
    rv = self.dispatch_request()
  File "c:\users\penie\brain_test\venv\lib\site-packages\flask\app.py", line 1499, in dispatch_request
    return self.ensure_sync(self.view_functions[rule.endpoint])(**req.view_args)
  File "c:\users\penie\brain_test\venv\lib\site-packages\flask_login\utils.py", line 272, in decorated_view
    return func(*args, **kwargs)
  File "C:\Users\penie\brain_test\app\routes.py", line 100, in uploader
    files = os.listdir('app/static/uploads')
FileNotFoundError: [WinError 3] The system cannot find the path specified: 'app/static/uploads'
2021-08-17 07:00:05,298 ERROR: Exception on /uploader [GET] [in c:\users\penie\brain_test\venv\lib\site-packages\flask\app.py:1454
Traceback (most recent call last):
  File "c:\users\penie\brain_test\venv\lib\site-packages\flask\app.py", line 2070, in wsgi_app
    response = self.full_dispatch_request()
  File "c:\users\penie\brain_test\venv\lib\site-packages\flask\app.py", line 1515, in full_dispatch_request
    rv = self.handle_user_exception(e)
  File "c:\users\penie\brain_test\venv\lib\site-packages\flask\app.py", line 1513, in full_dispatch_request
    rv = self.dispatch_request()
  File "c:\users\penie\brain_test\venv\lib\site-packages\flask\app.py", line 1499, in dispatch_request
    return self.ensure_sync(self.view_functions[rule.endpoint])(**req.view_args)
  File "c:\users\penie\brain_test\venv\lib\site-packages\flask_login\utils.py", line 272, in decorated_view
    return func(*args, **kwargs)
  File "C:\Users\penie\brain_test\app\routes.py", line 100, in uploader
    files = os.listdir('app/static/uploads')
FileNotFoundError: [WinError 3] The system cannot find the path specified: 'app/static/uploads'
2021-08-17 07:00:39,797 ERROR: Exception on /uploader [GET] [in c:\users\penie\brain_test\venv\lib\site-packages\flask\app.py:1454
Traceback (most recent call last):
  File "c:\users\penie\brain_test\venv\lib\site-packages\flask\app.py", line 2070, in wsgi_app
    response = self.full_dispatch_request()
  File "c:\users\penie\brain_test\venv\lib\site-packages\flask\app.py", line 1515, in full_dispatch_request
    rv = self.handle_user_exception(e)
  File "c:\users\penie\brain_test\venv\lib\site-packages\flask\app.py", line 1513, in full_dispatch_request
    rv = self.dispatch_request()
  File "c:\users\penie\brain_test\venv\lib\site-packages\flask\app.py", line 1499, in dispatch_request
    return self.ensure_sync(self.view_functions[rule.endpoint])(**req.view_args)
  File "c:\users\penie\brain_test\venv\lib\site-packages\flask_login\utils.py", line 272, in decorated_view
    return func(*args, **kwargs)
  File "C:\Users\penie\brain_test\app\routes.py", line 100, in uploader
    files = os.listdir('app/static/uploads')
FileNotFoundError: [WinError 3] The system cannot find the path specified: 'app/static/uploads'
