2021-09-16 12:44:16,982 ERROR: Exception on /download [GET] [in c:\users\penie\brain_test\venv\lib\site-packages\flask\app.py:1454
Traceback (most recent call last):
  File "c:\users\penie\brain_test\venv\lib\site-packages\flask\app.py", line 2070, in wsgi_app
    response = self.full_dispatch_request()
  File "c:\users\penie\brain_test\venv\lib\site-packages\flask\app.py", line 1515, in full_dispatch_request
    rv = self.handle_user_exception(e)
  File "c:\users\penie\brain_test\venv\lib\site-packages\flask\app.py", line 1513, in full_dispatch_request
    rv = self.dispatch_request()
  File "c:\users\penie\brain_test\venv\lib\site-packages\flask\app.py", line 1499, in dispatch_request
    return self.ensure_sync(self.view_functions[rule.endpoint])(**req.view_args)
  File "c:\users\penie\brain_test\venv\lib\site-packages\flask_login\utils.py", line 272, in decorated_view
    return func(*args, **kwargs)
  File "C:\Users\penie\brain_test\app\routes.py", line 196, in download
    file = open('ratings.csv', 'w')
PermissionError: [Errno 13] Permission denied: 'ratings.csv'
2021-09-30 11:48:49,930 ERROR: Exception on /download [GET] [in c:\users\penie\brain_test\venv\lib\site-packages\flask\app.py:1454
Traceback (most recent call last):
  File "c:\users\penie\brain_test\venv\lib\site-packages\flask\app.py", line 2070, in wsgi_app
    response = self.full_dispatch_request()
  File "c:\users\penie\brain_test\venv\lib\site-packages\flask\app.py", line 1515, in full_dispatch_request
    rv = self.handle_user_exception(e)
  File "c:\users\penie\brain_test\venv\lib\site-packages\flask\app.py", line 1513, in full_dispatch_request
    rv = self.dispatch_request()
  File "c:\users\penie\brain_test\venv\lib\site-packages\flask\app.py", line 1499, in dispatch_request
    return self.ensure_sync(self.view_functions[rule.endpoint])(**req.view_args)
  File "c:\users\penie\brain_test\venv\lib\site-packages\flask_login\utils.py", line 272, in decorated_view
    return func(*args, **kwargs)
  File "C:\Users\penie\brain_test\app\routes.py", line 198, in download
    with open('ratings.csv', 'w') as f:
PermissionError: [Errno 13] Permission denied: 'ratings.csv'
2021-09-30 11:50:07,006 ERROR: Exception on /download [GET] [in c:\users\penie\brain_test\venv\lib\site-packages\flask\app.py:1454
Traceback (most recent call last):
  File "c:\users\penie\brain_test\venv\lib\site-packages\flask\app.py", line 2070, in wsgi_app
    response = self.full_dispatch_request()
  File "c:\users\penie\brain_test\venv\lib\site-packages\flask\app.py", line 1515, in full_dispatch_request
    rv = self.handle_user_exception(e)
  File "c:\users\penie\brain_test\venv\lib\site-packages\flask\app.py", line 1513, in full_dispatch_request
    rv = self.dispatch_request()
  File "c:\users\penie\brain_test\venv\lib\site-packages\flask\app.py", line 1499, in dispatch_request
    return self.ensure_sync(self.view_functions[rule.endpoint])(**req.view_args)
  File "c:\users\penie\brain_test\venv\lib\site-packages\flask_login\utils.py", line 272, in decorated_view
    return func(*args, **kwargs)
  File "C:\Users\penie\brain_test\app\routes.py", line 198, in download
    f= open('ratings.csv', 'w')
PermissionError: [Errno 13] Permission denied: 'ratings.csv'
2021-09-30 11:53:15,115 ERROR: Exception on /download [GET] [in c:\users\penie\brain_test\venv\lib\site-packages\flask\app.py:1454
Traceback (most recent call last):
  File "c:\users\penie\brain_test\venv\lib\site-packages\flask\app.py", line 2070, in wsgi_app
    response = self.full_dispatch_request()
  File "c:\users\penie\brain_test\venv\lib\site-packages\flask\app.py", line 1515, in full_dispatch_request
    rv = self.handle_user_exception(e)
  File "c:\users\penie\brain_test\venv\lib\site-packages\flask\app.py", line 1513, in full_dispatch_request
    rv = self.dispatch_request()
  File "c:\users\penie\brain_test\venv\lib\site-packages\flask\app.py", line 1499, in dispatch_request
    return self.ensure_sync(self.view_functions[rule.endpoint])(**req.view_args)
  File "c:\users\penie\brain_test\venv\lib\site-packages\flask_login\utils.py", line 272, in decorated_view
    return func(*args, **kwargs)
  File "C:\Users\penie\brain_test\app\routes.py", line 198, in download
    with open('ratings.csv', 'w') as f:
PermissionError: [Errno 13] Permission denied: 'ratings.csv'
2021-09-30 11:53:56,795 ERROR: Exception on /download [GET] [in c:\users\penie\brain_test\venv\lib\site-packages\flask\app.py:1454
Traceback (most recent call last):
  File "c:\users\penie\brain_test\venv\lib\site-packages\flask\app.py", line 2070, in wsgi_app
    response = self.full_dispatch_request()
  File "c:\users\penie\brain_test\venv\lib\site-packages\flask\app.py", line 1515, in full_dispatch_request
    rv = self.handle_user_exception(e)
  File "c:\users\penie\brain_test\venv\lib\site-packages\flask\app.py", line 1513, in full_dispatch_request
    rv = self.dispatch_request()
  File "c:\users\penie\brain_test\venv\lib\site-packages\flask\app.py", line 1499, in dispatch_request
    return self.ensure_sync(self.view_functions[rule.endpoint])(**req.view_args)
  File "c:\users\penie\brain_test\venv\lib\site-packages\flask_login\utils.py", line 272, in decorated_view
    return func(*args, **kwargs)
  File "C:\Users\penie\brain_test\app\routes.py", line 198, in download
    with open('ratings.csv', 'w') as f:
PermissionError: [Errno 13] Permission denied: 'ratings.csv'
2021-09-30 11:56:07,391 ERROR: Exception on /download [GET] [in c:\users\penie\brain_test\venv\lib\site-packages\flask\app.py:1454
Traceback (most recent call last):
  File "c:\users\penie\brain_test\venv\lib\site-packages\flask\app.py", line 2070, in wsgi_app
    response = self.full_dispatch_request()
  File "c:\users\penie\brain_test\venv\lib\site-packages\flask\app.py", line 1515, in full_dispatch_request
    rv = self.handle_user_exception(e)
  File "c:\users\penie\brain_test\venv\lib\site-packages\flask\app.py", line 1513, in full_dispatch_request
    rv = self.dispatch_request()
  File "c:\users\penie\brain_test\venv\lib\site-packages\flask\app.py", line 1499, in dispatch_request
    return self.ensure_sync(self.view_functions[rule.endpoint])(**req.view_args)
  File "c:\users\penie\brain_test\venv\lib\site-packages\flask_login\utils.py", line 272, in decorated_view
    return func(*args, **kwargs)
  File "C:\Users\penie\brain_test\app\routes.py", line 208, in download
    return send_file('ratings.csv', as_attachment=True)
TypeError: send_file() missing 1 required positional argument: 'environ'
2021-09-30 11:56:12,260 ERROR: Exception on /download [GET] [in c:\users\penie\brain_test\venv\lib\site-packages\flask\app.py:1454
Traceback (most recent call last):
  File "c:\users\penie\brain_test\venv\lib\site-packages\flask\app.py", line 2070, in wsgi_app
    response = self.full_dispatch_request()
  File "c:\users\penie\brain_test\venv\lib\site-packages\flask\app.py", line 1515, in full_dispatch_request
    rv = self.handle_user_exception(e)
  File "c:\users\penie\brain_test\venv\lib\site-packages\flask\app.py", line 1513, in full_dispatch_request
    rv = self.dispatch_request()
  File "c:\users\penie\brain_test\venv\lib\site-packages\flask\app.py", line 1499, in dispatch_request
    return self.ensure_sync(self.view_functions[rule.endpoint])(**req.view_args)
  File "c:\users\penie\brain_test\venv\lib\site-packages\flask_login\utils.py", line 272, in decorated_view
    return func(*args, **kwargs)
  File "C:\Users\penie\brain_test\app\routes.py", line 208, in download
    return send_file('ratings.csv', as_attachment=True)
TypeError: send_file() missing 1 required positional argument: 'environ'
2021-09-30 11:57:42,403 ERROR: Exception on /download [GET] [in c:\users\penie\brain_test\venv\lib\site-packages\flask\app.py:1454
Traceback (most recent call last):
  File "c:\users\penie\brain_test\venv\lib\site-packages\flask\app.py", line 2070, in wsgi_app
    response = self.full_dispatch_request()
  File "c:\users\penie\brain_test\venv\lib\site-packages\flask\app.py", line 1515, in full_dispatch_request
    rv = self.handle_user_exception(e)
  File "c:\users\penie\brain_test\venv\lib\site-packages\flask\app.py", line 1513, in full_dispatch_request
    rv = self.dispatch_request()
  File "c:\users\penie\brain_test\venv\lib\site-packages\flask\app.py", line 1499, in dispatch_request
    return self.ensure_sync(self.view_functions[rule.endpoint])(**req.view_args)
  File "c:\users\penie\brain_test\venv\lib\site-packages\flask_login\utils.py", line 272, in decorated_view
    return func(*args, **kwargs)
  File "C:\Users\penie\brain_test\app\routes.py", line 208, in download
    return send_file('ratings.csv', as_attachment=True)
  File "c:\users\penie\brain_test\venv\lib\site-packages\flask\helpers.py", line 612, in send_file
    return werkzeug.utils.send_file(
  File "c:\users\penie\brain_test\venv\lib\site-packages\werkzeug\utils.py", line 697, in send_file
    stat = os.stat(path)
FileNotFoundError: [WinError 2] The system cannot find the file specified: 'C:\\Users\\penie\\brain_test\\app\\ratings.csv'
